Workbook

Sheet Revenue driver
B4: (In Millions) | C4: 43921 | D4: =EOMONTH(C4,12) -> 44286 | E4: =EOMONTH(D4,12) -> 44651 | F4: =EOMONTH(E4,12) -> 45016 | G4: =EOMONTH(F4,12) -> 45382 | H4: =EOMONTH(G4,12) -> 45747 | I4: =EOMONTH(H4,12) -> 46112 | K4: =EOMONTH(I4,12) -> 46477 | L4: =EOMONTH(K4,12) -> 46843 | M4: =EOMONTH(L4,12) -> 47208 | N4: =EOMONTH(M4,12) -> 47573 | O4: =EOMONTH(N4,12) -> 47938 | P4: =EOMONTH(O4,12) -> 48304 | Q4: =EOMONTH(P4,12) -> 48669 | R4: =EOMONTH(Q4,12) -> 49034 | S4: =EOMONTH(R4,12) -> 49399 | T4: =EOMONTH(S4,12) -> 49765
B5: Revenue driver:
B6: Revenue | C6: 248702 | D6: 241430.6 | E6: 309762.7 | F6: 428395.6 | G6: 507888.3 | H6: 593580.5 | I6: 688207.4 | K6: =AVERAGE(I9:K9)*K13 -> 914969.92 | L6: =AVERAGE(K9:L9)*L13 -> 1167507.9 | M6: =AVERAGE(L9:M9)*M13 -> 1467607.8 | N6: =AVERAGE(M9:N9)*N13 -> 1812809.9 | O6: =AVERAGE(N9:O9)*O13 -> 2203289.8 | P6: =AVERAGE(O9:P9)*P13 -> 2637618 | Q6: =AVERAGE(P9:Q9)*Q13 -> 3112542.8 | R6: =AVERAGE(Q9:R9)*R13 -> 3639457.9 | S6: =AVERAGE(R9:S9)*S13 -> 4219042.7 | T6: =AVERAGE(S9:T9)*T13 -> 4851117.8
B7: No. of stores | C7: 214 | D7: 234 | E7: 284 | F7: 324 | G7: 365 | H7: 415 | I7: 500 | K7: =I7+K8 -> 550 | L7: =K7+L8 -> 600 | M7: =L7+M8 -> 650 | N7: =M7+N8 -> 700 | O7: =N7+O8 -> 750 | P7: =O7+P8 -> 800 | Q7: =P7+Q8 -> 850 | R7: =Q7+R8 -> 900 | S7: =R7+S8 -> 950 | T7: =S7+T8 -> 1000
B8: Additions to the stores | C8: 0 | D8: =D7-C7 -> 20 | E8: =E7-D7 -> 50 | F8: =F7-E7 -> 40 | G8: =G7-F7 -> 41 | H8: =H7-G7 -> 50 | I8: 85 | K8: 50 | L8: 50 | M8: 50 | N8: 50 | O8: 50 | P8: 50 | Q8: 50 | R8: 50 | S8: 50 | T8: 50
B9: Retail sales area | C9: 7.8 | D9: 8.8 | E9: 11.5 | F9: 13.4 | G9: 15.1 | H9: 17.2 | I9: 20.6 | K9: =I9+K10 -> 23.1 | L9: =K9+L10 -> 25.6 | M9: =L9+M10 -> 28.1 | N9: =M9+N10 -> 30.6 | O9: =N9+O10 -> 33.1 | P9: =O9+P10 -> 35.6 | Q9: =P9+Q10 -> 38.1 | R9: =Q9+R10 -> 40.6 | S9: =R9+S10 -> 43.1 | T9: =S9+T10 -> 45.6
B10: Additions to retail sales area (sq.ft) | C10: 0 | D10: =D9-C9 -> 1 | E10: =E9-D9 -> 2.7 | F10: =F9-E9 -> 1.9 | G10: =G9-F9 -> 1.7 | H10: =H9-G9 -> 2.1 | I10: =I9-H9 -> 3.4 | K10: 2.5 | L10: 2.5 | M10: 2.5 | N10: 2.5 | O10: 2.5 | P10: 2.5 | Q10: 2.5 | R10: 2.5 | S10: 2.5 | T10: 2.5
B11: Average retail sales area per store | C11: 0 | D11: =D10*10^6/D8 -> 50000 | E11: =E10*10^6/E8 -> 54000 | F11: =F10*10^6/F8 -> 47500 | G11: =G10*10^6/G8 -> 41463.415 | H11: =H10*10^6/H8 -> 42000 | I11: =I10*10^6/I8 -> 40000 | K11: 44000 | L11: 44000 | M11: 44000 | N11: 44000 | O11: 44000 | P11: 44000 | Q11: 44000 | R11: 44000 | S11: 44000 | T11: 44000
B12: Revenue from sales from per retail sales area sq.ft | C12: 32879 | D12: 27306 | E12: 27454 | F12: 31096 | G12: 32941 | H12: 33869 | I12: 33422 | K12: 0 | L12: 0 | M12: 0 | N12: 0 | O12: 0 | P12: 0 | Q12: 0 | R12: 0 | S12: 0 | T12: 0
B13: Revenue per area sq.ft as calculated | C13: 0 | D13: =D6/AVERAGE(C9:D9) -> 29088.024 | E13: =E6/AVERAGE(D9:E9) -> 30518.493 | F13: =F6/AVERAGE(E9:F9) -> 34409.285 | G13: =G6/AVERAGE(F9:G9) -> 35641.284 | H13: =H6/AVERAGE(G9:H9) -> 36754.211 | I13: =I6/AVERAGE(H9:I9) -> 36413.09 | K13: =I13*(1+K14) -> 41875.053 | L13: =K13*(1+L14) -> 47946.936 | M13: =L13*(1+M14) -> 54659.507 | N13: =M13*(1+N14) -> 61765.243 | O13: =N13*(1+O14) -> 69177.072 | P13: =O13*(1+P14) -> 76786.55 | Q13: =P13*(1+Q14) -> 84465.205 | R13: =Q13*(1+R14) -> 92489.4 | S13: =R13*(1+S14) -> 100813.45 | T13: =S13*(1+T14) -> 109382.59
B14: Growth rate | C14: 0 | D14: 0 | E14: =E13/D13-1 -> 0.049177232 | F14: =F13/E13-1 -> 0.12748967 | G14: =G13/F13-1 -> 0.035804262 | H14: =H13/G13-1 -> 0.031225764 | I14: =I13/H13-1 -> -0.0092811293 | K14: =INDEX($K$18:$T$20,MATCH('P & L'!$D$5,$B$18:$B$20,0), MATCH(K$4,$K$4:$T$4,0)) -> 0.15 | L14: =INDEX($K$18:$T$20,MATCH('P & L'!$D$5,$B$18:$B$20,0), MATCH(L$4,$K$4:$T$4,0)) -> 0.145 | M14: =INDEX($K$18:$T$20,MATCH('P & L'!$D$5,$B$18:$B$20,0), MATCH(M$4,$K$4:$T$4,0)) -> 0.14 | N14: =INDEX($K$18:$T$20,MATCH('P & L'!$D$5,$B$18:$B$20,0), MATCH(N$4,$K$4:$T$4,0)) -> 0.13 | O14: =INDEX($K$18:$T$20,MATCH('P & L'!$D$5,$B$18:$B$20,0), MATCH(O$4,$K$4:$T$4,0)) -> 0.12 | P14: =INDEX($K$18:$T$20,MATCH('P & L'!$D$5,$B$18:$B$20,0), MATCH(P$4,$K$4:$T$4,0)) -> 0.11 | Q14: =INDEX($K$18:$T$20,MATCH('P & L'!$D$5,$B$18:$B$20,0), MATCH(Q$4,$K$4:$T$4,0)) -> 0.1 | R14: =INDEX($K$18:$T$20,MATCH('P & L'!$D$5,$B$18:$B$20,0), MATCH(R$4,$K$4:$T$4,0)) -> 0.095 | ... T14: =INDEX($K$18:$T$20,MATCH('P & L'!$D$5,$B$18:$B$20,0), MATCH(T$4,$K$4:$T$4,0)) -> 0.085
B15: Like for Like growth (24 months) | C15: 0.109 | D15: -0.131 | E15: 0.167 | F15: 0.242 | G15: 0.099 | H15: 0.084 | I15: 0.081 | K15: 0 | L15: 0 | M15: 0 | N15: 0 | O15: 0 | P15: 0 | Q15: 0 | R15: 0 | S15: 0 | T15: 0
B17: Growth rate:
B18: High | K18: 0.18 | L18: 0.175 | M18: 0.17 | N18: 0.16 | O18: 0.15 | P18: 0.14 | Q18: 0.13 | R18: 0.12 | S18: 0.11 | T18: 0.1
B19: Base | K19: 0.15 | L19: 0.145 | M19: 0.14 | N19: 0.13 | O19: 0.12 | P19: 0.11 | Q19: 0.1 | R19: 0.095 | S19: 0.09 | T19: 0.085
B20: Low | K20: 0.12 | L20: 0.11 | M20: 0.105 | N20: 0.1 | O20: 0.095 | P20: 0.09 | Q20: 0.085 | R20: 0.08 | S20: 0.075 | T20: 0.07

Sheet Working Capital
C3: =D4-C4 -> 365 | D3: =E4-D4 -> 365 | E3: =F4-E4 -> 365 | F3: =G4-F4 -> 366 | G3: =H4-G4 -> 365 | H3: =I4-H4 -> 365 | I3: =K4-I4 -> 365 | K3: =L4-K4 -> 366 | L3: =M4-L4 -> 365 | M3: =N4-M4 -> 365 | N3: =O4-N4 -> 365 | O3: =P4-O4 -> 366 | P3: 366 | Q3: 366 | R3: 366 | S3: 366 | T3: 366
B4: (In Millions) | C4: 43921 | D4: =EOMONTH(C4,12) -> 44286 | E4: =EOMONTH(D4,12) -> 44651 | F4: =EOMONTH(E4,12) -> 45016 | G4: =EOMONTH(F4,12) -> 45382 | H4: =EOMONTH(G4,12) -> 45747 | I4: =EOMONTH(H4,12) -> 46112 | K4: =EOMONTH(I4,12) -> 46477 | L4: =EOMONTH(K4,12) -> 46843 | M4: =EOMONTH(L4,12) -> 47208 | N4: =EOMONTH(M4,12) -> 47573 | O4: =EOMONTH(N4,12) -> 47938 | P4: =EOMONTH(O4,12) -> 48304 | Q4: =EOMONTH(P4,12) -> 48669 | R4: =EOMONTH(Q4,12) -> 49034 | S4: =EOMONTH(R4,12) -> 49399 | T4: =EOMONTH(S4,12) -> 49765
B5: Working Capital Schedule:
B6: Inventory:
B7: Average inventories | C7: 0 | D7: =AVERAGE(BS!C24:D24) -> 20978.4 | E7: =AVERAGE(BS!D24:E24) -> 24954.7 | F7: =AVERAGE(BS!E24:F24) -> 29930.7 | G7: =AVERAGE(BS!F24:G24) -> 35853.95 | H7: =AVERAGE(BS!G24:H24) -> 44858.4 | I7: =AVERAGE(BS!H24:I24) -> 54725.05 | K7: =K10/K3*K8 -> 70358.056 | L7: =L10/L3*L8 -> 90023.328 | M7: =M10/M3*M8 -> 113163.21 | N7: =N10/N3*N8 -> 139780.79 | O7: =O10/O3*O8 -> 169425.44 | P7: =P10/P3*P8 -> 202823.8 | Q7: =Q10/Q3*Q8 -> 239343.89 | R7: =R10/R3*R8 -> 279861.86 | ... T7: =T10/T3*T8 -> 373034.36
B8: Total COGS | C8: 0 | D8: =-'P & L'!D11 -> 205546.8 | E8: =-'P & L'!E11 -> 263973.9 | F8: =-'P & L'!F11 -> 363839.5 | G8: =-'P & L'!G11 -> 432745.4 | H8: =-'P & L'!H11 -> 505517 | I8: =-'P & L'!I11 -> 584597.3 | K8: =-'P & L'!K11 -> 777724.43 | L8: =-'P & L'!L11 -> 992381.71 | M8: =-'P & L'!M11 -> 1247466.6 | N8: =-'P & L'!N11 -> 1540888.4 | O8: =-'P & L'!O11 -> 1872796.3 | P8: =-'P & L'!P11 -> 2241975.3 | Q8: =-'P & L'!Q11 -> 2645661.4 | R8: =-'P & L'!R11 -> 3093539.2 | ... T8: =-'P & L'!T11 -> 4123450.1
B9: Inventry turn-over ratio | C9: 0 | D9: =D8/D7 -> 9.7980208 | E9: =E8/E7 -> 10.578124 | F9: =F8/F7 -> 12.156064 | G9: =G8/G7 -> 12.069672 | H9: =H8/H7 -> 11.269171 | I9: =I8/I7 -> 10.682444 | K9: =AVERAGE($D$9:$I$9) -> 11.092249 | L9: =AVERAGE($D$9:$I$9) -> 11.092249 | M9: =AVERAGE($D$9:$I$9) -> 11.092249 | N9: =AVERAGE($D$9:$I$9) -> 11.092249 | O9: =AVERAGE($D$9:$I$9) -> 11.092249 | P9: =AVERAGE($D$9:$I$9) -> 11.092249 | Q9: =AVERAGE($D$9:$I$9) -> 11.092249 | R9: =AVERAGE($D$9:$I$9) -> 11.092249 | ... T9: =AVERAGE($D$9:$I$9) -> 11.092249
B10: No.of days in inventory | C10: 0 | D10: =D3/D9 -> 37.252421 | E10: =E3/E9 -> 34.505175 | F10: =F3/F9 -> 30.10843 | G10: =G3/G9 -> 30.241088 | H10: =H3/H9 -> 32.389249 | I10: =I3/I9 -> 34.16821 | K10: =AVERAGE($D$10:$I$10) -> 33.110762 | L10: =AVERAGE($D$10:$I$10) -> 33.110762 | M10: =AVERAGE($D$10:$I$10) -> 33.110762 | N10: =AVERAGE($D$10:$I$10) -> 33.110762 | O10: =AVERAGE($D$10:$I$10) -> 33.110762 | P10: =AVERAGE($D$10:$I$10) -> 33.110762 | Q10: =AVERAGE($D$10:$I$10) -> 33.110762 | R10: =AVERAGE($D$10:$I$10) -> 33.110762 | ... T10: =AVERAGE($D$10:$I$10) -> 33.110762
B12: Receivables:
B13: Average trade receivables | C13: 0 | D13: =AVERAGE(BS!C27:D27) -> 315.65 | E13: =AVERAGE(BS!D27:E27) -> 552.35 | F13: =AVERAGE(BS!E27:F27) -> 645.25 | G13: =AVERAGE(BS!F27:G27) -> 1142.65 | H13: =AVERAGE(BS!G27:H27) -> 1600.8 | I13: =AVERAGE(BS!H27:I27) -> 1515.65 | K13: =K16*K14/K3 -> 1786.8988 | L13: =L16*L14/L3 -> 2286.3419 | M13: =M16*M14/M3 -> 2874.0304 | N13: =N16*N14/N3 -> 3550.043 | O13: =O16*O14/O3 -> 4302.9346 | P13: =P16*P14/P3 -> 5151.1599 | Q13: =Q16*Q14/Q3 -> 6078.6686 | R13: =R16*R14/R3 -> 7107.7121 | ... T13: =T16*T14/T3 -> 9474.0343
B14: Revenue from operations | C14: 0 | D14: ='P & L'!D8 -> 241430.6 | E14: ='P & L'!E8 -> 309762.7 | F14: ='P & L'!F8 -> 428395.6 | G14: ='P & L'!G8 -> 507888.3 | H14: ='P & L'!H8 -> 593580.5 | I14: ='P & L'!I8 -> 688207.4 | K14: ='P & L'!K8 -> 914969.92 | L14: ='P & L'!L8 -> 1167507.9 | M14: ='P & L'!M8 -> 1467607.8 | N14: ='P & L'!N8 -> 1812809.9 | O14: ='P & L'!O8 -> 2203289.8 | P14: ='P & L'!P8 -> 2637618 | Q14: ='P & L'!Q8 -> 3112542.8 | R14: ='P & L'!R8 -> 3639457.9 | ... T14: ='P & L'!T8 -> 4851117.8
B15: Receivables turn-over ratio | C15: 0 | D15: =D14/D13 -> 764.86805 | E15: =E14/E13 -> 560.80873 | F15: =F14/F13 -> 663.92189 | G15: =G14/G13 -> 444.48283 | H15: =H14/H13 -> 370.80241 | I15: =I14/I13 -> 454.0675 | K15: =AVERAGE($D$15:$I$15) -> 543.15857 | L15: =AVERAGE($D$15:$I$15) -> 543.15857 | M15: =AVERAGE($D$15:$I$15) -> 543.15857 | N15: =AVERAGE($D$15:$I$15) -> 543.15857 | O15: =AVERAGE($D$15:$I$15) -> 543.15857 | P15: =AVERAGE($D$15:$I$15) -> 543.15857 | Q15: =AVERAGE($D$15:$I$15) -> 543.15857 | R15: =AVERAGE($D$15:$I$15) -> 543.15857 | ... T15: =AVERAGE($D$15:$I$15) -> 543.15857
B16: No.of days for receivables | C16: 0 | D16: =D3/D15 -> 0.47720649 | E16: =E3/E15 -> 0.65084579 | F16: =F3/F15 -> 0.55126967 | G16: =G3/G15 -> 0.82117909 | H16: =H3/H15 -> 0.98435174 | I16: =I3/I15 -> 0.80384525 | K16: =AVERAGE($D$16:$I$16) -> 0.71478301 | L16: =AVERAGE($D$16:$I$16) -> 0.71478301 | M16: =AVERAGE($D$16:$I$16) -> 0.71478301 | N16: =AVERAGE($D$16:$I$16) -> 0.71478301 | O16: =AVERAGE($D$16:$I$16) -> 0.71478301 | P16: =AVERAGE($D$16:$I$16) -> 0.71478301 | Q16: =AVERAGE($D$16:$I$16) -> 0.71478301 | R16: =AVERAGE($D$16:$I$16) -> 0.71478301 | ... T16: =AVERAGE($D$16:$I$16) -> 0.71478301
B18: Payables:
B19: Micro and small enterprises | C19: =BS!C56 -> 174.7 | D19: =BS!D56 -> 219.5 | E19: =BS!E56 -> 323.9 | F19: =BS!F56 -> 762.9 | G19: =BS!G56 -> 2306 | H19: =BS!H56 -> 2895.3 | I19: =BS!I56 -> 3934.7 | K19: =K21*K22 -> 4344.1019 | L19: =L21*L22 -> 5558.2904 | M19: =M21*M22 -> 6987.0107 | N19: =N21*N22 -> 8630.4545 | O19: =O21*O22 -> 10460.798 | P19: =P21*P22 -> 12522.905 | Q19: =Q21*Q22 -> 14777.757 | R19: =R21*R22 -> 17279.449 | ... T19: =T21*T22 -> 23032.178
B20: Other than micro and small enterprises | C20: =BS!C57 -> 4159.8 | D20: =BS!D57 -> 5561.8 | E20: =BS!E57 -> 5568.1 | F20: =BS!F57 -> 6775 | G20: =BS!G57 -> 7542.1 | H20: =BS!H57 -> 7812.8 | I20: =BS!I57 -> 9447.6 | K20: =K21-K19 -> 11975.581 | L20: =L21-L19 -> 15322.789 | M20: =M21-M19 -> 19261.407 | N20: =N21-N19 -> 23791.963 | O20: =O21-O19 -> 28837.752 | P20: =P21-P19 -> 34522.456 | Q20: =Q21-Q19 -> 40738.508 | R20: =R21-R19 -> 47635.034 | ... T20: =T21-T19 -> 63493.842
B21: Total Payables: | C21: =SUM(C19:C20) -> 4334.5 | D21: =SUM(D19:D20) -> 5781.3 | E21: =SUM(E19:E20) -> 5892 | F21: =SUM(F19:F20) -> 7537.9 | G21: =SUM(G19:G20) -> 9848.1 | H21: =SUM(H19:H20) -> 10708.1 | I21: =SUM(I19:I20) -> 13382.3 | K21: =K24 -> 16319.683 | L21: =L24 -> 20881.08 | M21: =M24 -> 26248.418 | N21: =N24 -> 32422.417 | O21: =O24 -> 39298.549 | P21: =P24 -> 47045.361 | Q21: =Q24 -> 55516.265 | R21: =R24 -> 64914.483 | ... T21: =T24 -> 86526.02
B22: Micro and small as a percentage of total | C22: =C19/C21 -> 0.040304533 | D22: =D19/D21 -> 0.037967239 | E22: =E19/E21 -> 0.054972845 | F22: =F19/F21 -> 0.10120856 | G22: =G19/G21 -> 0.23415684 | H22: =H19/H21 -> 0.2703841 | I22: =I19/I21 -> 0.2940227 | K22: =AVERAGE($G$22:$I$22) -> 0.26618788 | L22: =AVERAGE($G$22:$I$22) -> 0.26618788 | M22: =AVERAGE($G$22:$I$22) -> 0.26618788 | N22: =AVERAGE($G$22:$I$22) -> 0.26618788 | O22: =AVERAGE($G$22:$I$22) -> 0.26618788 | P22: =AVERAGE($G$22:$I$22) -> 0.26618788 | Q22: =AVERAGE($G$22:$I$22) -> 0.26618788 | R22: =AVERAGE($G$22:$I$22) -> 0.26618788 | ... T22: =AVERAGE($G$22:$I$22) -> 0.26618788
B24: Average trade payables | C24: 0 | D24: =AVERAGE(C21:D21) -> 5057.9 | E24: =AVERAGE(D21:E21) -> 5836.65 | F24: =AVERAGE(E21:F21) -> 6714.95 | G24: =AVERAGE(F21:G21) -> 8693 | H24: =AVERAGE(G21:H21) -> 10278.1 | I24: =AVERAGE(H21:I21) -> 12045.2 | K24: =K25/K26 -> 16319.683 | L24: =L25/L26 -> 20881.08 | M24: =M25/M26 -> 26248.418 | N24: =N25/N26 -> 32422.417 | O24: =O25/O26 -> 39298.549 | P24: =P25/P26 -> 47045.361 | Q24: =Q25/Q26 -> 55516.265 | R24: =R25/R26 -> 64914.483 | ... T24: =T25/T26 -> 86526.02
B25: Total COGS | C25: 0 | D25: =-'P & L'!D11 -> 205546.8 | E25: =-'P & L'!E11 -> 263973.9 | F25: =-'P & L'!F11 -> 363839.5 | G25: =-'P & L'!G11 -> 432745.4 | H25: =-'P & L'!H11 -> 505517 | I25: =-'P & L'!I11 -> 584597.3 | J25: =-'P & L'!J11 -> 0 | K25: =-'P & L'!K11 -> 777724.43 | ... T25: =-'P & L'!T11 -> 4123450.1
B26: Payables turn-over ratio | C26: 0 | D26: =D25/D24 -> 40.638763 | E26: =E25/E24 -> 45.226954 | F26: =F25/F24 -> 54.183501 | G26: =G25/G24 -> 49.780904 | H26: =H25/H24 -> 49.183896 | I26: =I25/I24 -> 48.533632 | K26: =K3/K27 -> 47.655609 | L26: =L3/L27 -> 47.525402 | M26: =M3/M27 -> 47.525402 | N26: =N3/N27 -> 47.525402 | O26: =O3/O27 -> 47.655609 | P26: =P3/P27 -> 47.655609 | Q26: =Q3/Q27 -> 47.655609 | R26: =R3/R27 -> 47.655609 | ... T26: =T3/T27 -> 47.655609
B27: No.of days for payables | C27: 0 | D27: =D3/D26 -> 8.9815726 | E27: =E3/E26 -> 8.0704087 | F27: =F3/F26 -> 6.7548238 | G27: =G3/G26 -> 7.3321288 | H27: =H3/H26 -> 7.4211283 | I27: =I3/I26 -> 7.5205582 | K27: =AVERAGE($D$27:$I$27) -> 7.6801034 | L27: =AVERAGE($D$27:$I$27) -> 7.6801034 | M27: =AVERAGE($D$27:$I$27) -> 7.6801034 | N27: =AVERAGE($D$27:$I$27) -> 7.6801034 | O27: =AVERAGE($D$27:$I$27) -> 7.6801034 | P27: =AVERAGE($D$27:$I$27) -> 7.6801034 | Q27: =AVERAGE($D$27:$I$27) -> 7.6801034 | R27: =AVERAGE($D$27:$I$27) -> 7.6801034 | ... T27: =AVERAGE($D$27:$I$27) -> 7.6801034
B29: Current Liabilitiess:
B30: Current Tax Liabilities:
B31: Current Tax Liabilities (Net) | C31: =BS!C61 -> 151.8 | D31: =BS!D61 -> 237.7 | E31: =BS!E61 -> 364.4 | F31: =BS!F61 -> 853.9 | G31: =BS!G61 -> 2547.8 | H31: =BS!H61 -> 2411.2 | I31: =BS!I61 -> 2715.3 | K31: =K32*K33 -> 4037.1598 | L31: =L32*L33 -> 5324.4069 | M31: =M32*M33 -> 6837.5954 | N31: =N32*N33 -> 8585.5569 | O31: =O32*O33 -> 10571.168 | P31: =P32*P33 -> 12786.69 | Q31: =Q32*Q33 -> 15214.678 | R31: =R32*R33 -> 17915.854 | ... T31: =T32*T33 -> 24147.517
B32: Total Tax | C32: =-'P & L'!C30 -> 4437.9 | D32: =-'P & L'!D30 -> 3840.2 | E32: =-'P & L'!E30 -> 5717.2 | F32: =-'P & L'!F30 -> 6817.5 | G32: =-'P & L'!G30 -> 9257.2 | H32: =-'P & L'!H30 -> 9652.2 | I32: =-'P & L'!I30 -> 11110.2 | J32: =-'P & L'!J30 -> 0 | ... T32: =-'P & L'!T30 -> 107960.44
B33: Current Tax Liability as a % of total tax | C33: =C31/C32 -> 0.034205367 | D33: =D31/D32 -> 0.061897818 | E33: =E31/E32 -> 0.063737494 | F33: =F31/F32 -> 0.12525119 | G33: =G31/G32 -> 0.27522361 | H33: =H31/H32 -> 0.24980833 | I33: =I31/I32 -> 0.24439704 | K33: =AVERAGE($F$33:$I$33) -> 0.22367004 | L33: =AVERAGE($F$33:$I$33) -> 0.22367004 | M33: =AVERAGE($F$33:$I$33) -> 0.22367004 | N33: =AVERAGE($F$33:$I$33) -> 0.22367004 | O33: =AVERAGE($F$33:$I$33) -> 0.22367004 | P33: =AVERAGE($F$33:$I$33) -> 0.22367004 | Q33: =AVERAGE($F$33:$I$33) -> 0.22367004 | R33: =AVERAGE($F$33:$I$33) -> 0.22367004 | ... T33: =AVERAGE($F$33:$I$33) -> 0.22367004
B35: Other current financial liabilities:
B36: Other current financial liabilities | C36: =BS!C58 -> 1779.4 | D36: =BS!D58 -> 2697.8 | E36: =BS!E58 -> 2829.2 | F36: =BS!F58 -> 2894.6 | G36: =BS!G58 -> 3898.5 | H36: =BS!H58 -> 4486.4 | I36: =BS!I58 -> 6371.9 | K36: =K37*Schedules!K8 -> 2475.1087 | L36: =L37*Schedules!L8 -> 5016.993 | M36: =M37*Schedules!M8 -> 5673.0613 | N36: =N37*Schedules!N8 -> 6139.0628 | O36: =O37*Schedules!O8 -> 6613.8169 | P36: =P37*Schedules!P8 -> 7097.4523 | Q36: =Q37*Schedules!Q8 -> 7590.099 | R36: =R37*Schedules!R8 -> 8091.8889 | ... T36: =T37*Schedules!T8 -> 9123.4344
B37: Other current financial liabilities as a % of capex | C37: =C36/Schedules!C8 -> 0.11955361 | D37: =D36/Schedules!D8 -> 0.23687977 | E37: =E36/Schedules!E8 -> 0.13152585 | F37: =F36/Schedules!F8 -> 0.11949405 | G37: =G36/Schedules!G8 -> 0.15117966 | H37: =H36/Schedules!H8 -> 0.13867715 | I37: =I36/Schedules!I8 -> 0.15882856 | K37: =AVERAGE($C$37:$I$37) -> 0.15087695 | L37: =AVERAGE($C$37:$I$37) -> 0.15087695 | M37: =AVERAGE($C$37:$I$37) -> 0.15087695 | N37: =AVERAGE($C$37:$I$37) -> 0.15087695 | O37: =AVERAGE($C$37:$I$37) -> 0.15087695 | P37: =AVERAGE($C$37:$I$37) -> 0.15087695 | Q37: =AVERAGE($C$37:$I$37) -> 0.15087695 | R37: =AVERAGE($C$37:$I$37) -> 0.15087695 | ... T37: =AVERAGE($C$37:$I$37) -> 0.15087695
B39: Provisions:
B40: Closing balance of provision | C40: =BS!C60 -> 207 | D40: =BS!D60 -> 407.3 | E40: =BS!E60 -> 583.7 | F40: =BS!F60 -> 508.7 | G40: =BS!G60 -> 610.4 | H40: =BS!H60 -> 491.4 | I40: =BS!I60 -> 1114.2 | K40: =K41*K42 -> 1198.6249 | L40: =L41*L42 -> 1529.4536 | M40: =M41*M42 -> 1922.5891 | N40: =N41*N42 -> 2374.8093 | O40: =O41*O42 -> 2886.3441 | P40: =P41*P42 -> 3455.3209 | Q40: =Q41*Q42 -> 4077.4798 | R40: =R41*R42 -> 4767.7468 | ... T40: =T41*T42 -> 6355.0402
B41: Employee benefit during the year | C41: =-'P & L'!C14 -> 4561 | D41: =-'P & L'!D14 -> 5365.7 | E41: =-'P & L'!E14 -> 6162.1 | F41: =-'P & L'!F14 -> 7469.7 | G41: =-'P & L'!G14 -> 9061.2 | H41: =-'P & L'!H14 -> 11659 | I41: =-'P & L'!I14 -> 15414.8 | K41: =-'P & L'!K14 -> 18008.5 | L41: =-'P & L'!L14 -> 22978.97 | M41: =-'P & L'!M14 -> 28885.556 | N41: =-'P & L'!N14 -> 35679.847 | O41: =-'P & L'!O14 -> 43365.299 | P41: =-'P & L'!P14 -> 51913.777 | Q41: =-'P & L'!Q14 -> 61261.279 | R41: =-'P & L'!R14 -> 71632.057 | ... T41: =-'P & L'!T14 -> 95480.03
B42: Provision as a % of employee benefit | C42: =C40/C41 -> 0.045384784 | D42: =D40/D41 -> 0.075908083 | E42: =E40/E41 -> 0.094724201 | F42: =F40/F41 -> 0.068101798 | G42: =G40/G41 -> 0.067364146 | H42: =H40/H41 -> 0.042147697 | I42: =I40/I41 -> 0.072281184 | K42: =AVERAGE($C$42:$I$42) -> 0.066558842 | L42: =AVERAGE($C$42:$I$42) -> 0.066558842 | M42: =AVERAGE($C$42:$I$42) -> 0.066558842 | N42: =AVERAGE($C$42:$I$42) -> 0.066558842 | O42: =AVERAGE($C$42:$I$42) -> 0.066558842 | P42: =AVERAGE($C$42:$I$42) -> 0.066558842 | Q42: =AVERAGE($C$42:$I$42) -> 0.066558842 | R42: =AVERAGE($C$42:$I$42) -> 0.066558842 | ... T42: =AVERAGE($C$42:$I$42) -> 0.066558842
B44: Other current liabilities:
B45: Statutary dues | C45: 181.6 | D45: 371.2 | E45: 469.8 | F45: 954.6 | G45: 679 | H45: 959.6 | I45: 786.2 | K45: =K50*'P & L'!K8 -> 1321.2922 | L45: =L50*'P & L'!L8 -> 1685.9779 | M45: =M50*'P & L'!M8 -> 2119.3469 | N45: =N50*'P & L'!N8 -> 2617.8472 | O45: =O50*'P & L'!O8 -> 3181.7324 | P45: =P50*'P & L'!P8 -> 3808.9383 | Q45: =Q50*'P & L'!Q8 -> 4494.769 | R45: =R50*'P & L'!R8 -> 5255.6779 | ... T45: =T50*'P & L'!T8 -> 7005.4149
B46: Others payable | C46: 25.4 | D46: 36.1 | E46: 92.3 | F46: 183.4 | G46: 205.9 | H46: 233.2 | I46: 280 | K46: =K51*'P & L'!K8 -> 285.32198 | L46: =L51*'P & L'!L8 -> 364.07281 | M46: =M51*'P & L'!M8 -> 457.65522 | N46: =N51*'P & L'!N8 -> 565.3022 | O46: =O51*'P & L'!O8 -> 687.06849 | P46: =P51*'P & L'!P8 -> 822.50835 | Q46: =Q51*'P & L'!Q8 -> 970.60774 | R46: =R51*'P & L'!R8 -> 1134.9196 | ... T46: =T51*'P & L'!T8 -> 1512.7607
B47: Corporate Social Responsibility (CSR) | C47: 0 | D47: 0 | E47: 21.6 | F47: 73.8 | G47: 72.5 | H47: 193.4 | I47: 348.2 | K47: =K52*'P & L'!K32 -> 572.02077 | L47: =L52*'P & L'!L32 -> 754.40941 | M47: =M52*'P & L'!M32 -> 968.81144 | N47: =N52*'P & L'!N32 -> 1216.4782 | O47: =O52*'P & L'!O32 -> 1497.8174 | P47: =P52*'P & L'!P32 -> 1811.7322 | Q47: =Q52*'P & L'!Q32 -> 2155.7512 | R47: =R52*'P & L'!R32 -> 2538.4778 | ... T47: =T52*'P & L'!T32 -> 3421.4354
B48: Oter current liabilities total | C48: =SUM(C45:C47) -> 207 | D48: =SUM(D45:D47) -> 407.3 | E48: =SUM(E45:E47) -> 583.7 | F48: =SUM(F45:F47) -> 1211.8 | G48: =SUM(G45:G47) -> 957.4 | H48: =SUM(H45:H47) -> 1386.2 | I48: =SUM(I45:I47) -> 1414.4 | K48: =SUM(K45:K47) -> 2178.6349 | L48: =SUM(L45:L47) -> 2804.4601 | M48: =SUM(M45:M47) -> 3545.8135 | N48: =SUM(N45:N47) -> 4399.6276 | O48: =SUM(O45:O47) -> 5366.6183 | P48: =SUM(P45:P47) -> 6443.1789 | Q48: =SUM(Q45:Q47) -> 7621.1279 | R48: =SUM(R45:R47) -> 8929.0753 | ... T48: =SUM(T45:T47) -> 11939.611
B50: Statutary dues as a % of revenue | C50: =C45/'P & L'!C8 -> 0.00073019115 | D50: =D45/'P & L'!D8 -> 0.0015375019 | E50: =E45/'P & L'!E8 -> 0.0015166448 | F50: =F45/'P & L'!F8 -> 0.0022283142 | G50: =G45/'P & L'!G8 -> 0.0013369081 | H50: =H45/'P & L'!H8 -> 0.0016166299 | I50: =I45/'P & L'!I8 -> 0.0011423882 | K50: =AVERAGE($C$50:$I$50) -> 0.0014440826 | L50: =AVERAGE($C$50:$I$50) -> 0.0014440826 | M50: =AVERAGE($C$50:$I$50) -> 0.0014440826 | N50: =AVERAGE($C$50:$I$50) -> 0.0014440826 | O50: =AVERAGE($C$50:$I$50) -> 0.0014440826 | P50: =AVERAGE($C$50:$I$50) -> 0.0014440826 | Q50: =AVERAGE($C$50:$I$50) -> 0.0014440826 | R50: =AVERAGE($C$50:$I$50) -> 0.0014440826 | ... T50: =AVERAGE($C$50:$I$50) -> 0.0014440826
...

Sheet Schedules
B4: (In Millions) | C4: 43921 | D4: =EOMONTH(C4,12) -> 44286 | E4: =EOMONTH(D4,12) -> 44651 | F4: =EOMONTH(E4,12) -> 45016 | G4: =EOMONTH(F4,12) -> 45382 | H4: =EOMONTH(G4,12) -> 45747 | I4: =EOMONTH(H4,12) -> 46112 | K4: =EOMONTH(I4,12) -> 46477 | L4: =EOMONTH(K4,12) -> 46843 | M4: =EOMONTH(L4,12) -> 47208 | N4: =EOMONTH(M4,12) -> 47573 | O4: =EOMONTH(N4,12) -> 47938 | P4: =EOMONTH(O4,12) -> 48304 | Q4: =EOMONTH(P4,12) -> 48669 | R4: =EOMONTH(Q4,12) -> 49034 | S4: =EOMONTH(R4,12) -> 49399 | T4: =EOMONTH(S4,12) -> 49765
B5: Depreciation Schedule:
B6: PPE:
B7: Opening balance | C7: =48575.5-5835.2 -> 42740.3 | D7: =C11 -> 51073.6 | E7: =D11 -> 59385 | F7: =E11 -> 77704.6 | G7: =F11 -> 97256.1 | H7: =G11 -> 117591.9 | I7: =H11 -> 143498.3 | K7: =I11 -> 175869.5 | L7: =K11 -> 183070.72 | M7: =L11 -> 206338.1 | N7: =M11 -> 232681.76 | O7: =N11 -> 260719.64 | P7: =O11 -> 290423.6 | Q7: =P11 -> 321767.72 | R7: =Q11 -> 354728.22 | S7: =R11 -> 389283.37 | T7: =S11 -> 425413.39
B8: Additions | C8: 14883.7 | D8: 11388.9 | E8: 21510.6 | F8: 24223.8 | G8: 25787.2 | H8: 32351.4 | I8: 40118.1 | K8: =-K28 -> 16404.817 | L8: =-L28 -> 33252.217 | M8: =-M28 -> 37600.583 | N8: =-N28 -> 40689.203 | O8: =-O28 -> 43835.834 | P8: =-P28 -> 47041.33 | Q8: =-Q28 -> 50306.551 | R8: =-R28 -> 53632.373 | ... T8: =-T28 -> 60469.372
B9: Depreciation | C9: -2618.7 | D9: -2892.3 | E9: -3399.8 | F9: -4595.9 | G9: -5336.5 | H9: -6327.3 | I9: -7659.7 | K9: =K15*(K7+K8/2) -> -9203.5954 | L9: =L15*(L7+L8/2) -> -9984.8415 | M9: =M15*(M7+M8/2) -> -11256.919 | N9: =N15*(N7+N8/2) -> -12651.318 | O9: =O15*(O7+O8/2) -> -14131.878 | P9: =P15*(P7+P8/2) -> -15697.213 | Q9: =Q15*(Q7+Q8/2) -> -17346.05 | R9: =R15*(R7+R8/2) -> -19077.22 | ... T9: =T15*(T7+T8/2) -> -22782.404
B10: Others | C10: =C11-SUM(C7:C9) -> -3931.7 | D10: =D11-SUM(D7:D9) -> -185.2 | E10: =E11-SUM(E7:E9) -> 208.8 | F10: =F11-SUM(F7:F9) -> -76.4 | G10: =G11-SUM(G7:G9) -> -114.9 | H10: =H11-SUM(H7:H9) -> -117.7 | I10: =I11-SUM(I7:I9) -> -87.2 | K10: 0 | L10: 0 | M10: 0 | N10: 0 | O10: 0 | P10: 0 | Q10: 0 | R10: 0 | S10: 0 | T10: 0
B11: Closing balance | C11: 51073.6 | D11: 59385 | E11: 77704.6 | F11: 97256.1 | G11: 117591.9 | H11: 143498.3 | I11: 175869.5 | K11: =SUM(K7:K10) -> 183070.72 | L11: =SUM(L7:L10) -> 206338.1 | M11: =SUM(M7:M10) -> 232681.76 | N11: =SUM(N7:N10) -> 260719.64 | O11: =SUM(O7:O10) -> 290423.6 | P11: =SUM(P7:P10) -> 321767.72 | Q11: =SUM(Q7:Q10) -> 354728.22 | R11: =SUM(R7:R10) -> 389283.37 | ... T11: =SUM(T7:T10) -> 463100.36
B13: Additional stores per year | C13: ='Revenue driver'!C8 -> 0 | D13: ='Revenue driver'!D8 -> 20 | E13: ='Revenue driver'!E8 -> 50 | F13: ='Revenue driver'!F8 -> 40 | G13: ='Revenue driver'!G8 -> 41 | H13: ='Revenue driver'!H8 -> 50 | I13: ='Revenue driver'!I8 -> 85 | K13: ='Revenue driver'!K8 -> 50 | L13: ='Revenue driver'!L8 -> 50 | M13: ='Revenue driver'!M8 -> 50 | N13: ='Revenue driver'!N8 -> 50 | O13: ='Revenue driver'!O8 -> 50 | P13: ='Revenue driver'!P8 -> 50 | Q13: ='Revenue driver'!Q8 -> 50 | R13: ='Revenue driver'!R8 -> 50 | ... T13: ='Revenue driver'!T8 -> 50
B14: Cost per new store | C14: 0 | D14: =D8/D13 -> 569.445 | E14: =E8/E13 -> 430.212 | F14: =F8/F13 -> 605.595 | G14: =G8/G13 -> 628.9561 | H14: =H8/H13 -> 647.028 | I14: =I8/I13 -> 471.97765 | K14: 650 | L14: =K14+L13 -> 700 | M14: =L14+M13 -> 750 | N14: =M14+N13 -> 800 | O14: =N14+O13 -> 850 | P14: =O14+P13 -> 900 | Q14: =P14+Q13 -> 950 | R14: =Q14+R13 -> 1000 | S14: =R14+S13 -> 1050 | T14: =S14+T13 -> 1100
B15: Depreciation rate | C15: =C9/(C8/2+C7) -> -0.052183894 | D15: =D9/(D8/2+D7) -> -0.050949434 | E15: =E9/(E8/2+E7) -> -0.048471421 | F15: =F9/(F8/2+F7) -> -0.051169885 | G15: =G9/(G8/2+G7) -> -0.048447703 | H15: =H9/(H8/2+H7) -> -0.047300692 | I15: =I9/(I8/2+I7) -> -0.046831891 | K15: -0.05 | L15: -0.05 | M15: -0.05 | N15: -0.05 | O15: -0.05 | P15: -0.05 | Q15: -0.05 | R15: -0.05 | S15: -0.05 | T15: -0.05
B17: Right of use:
B18: Opening balance | D18: 7173.3 | E18: 9602.4 | F18: 13886.5 | G18: 15048.8 | H18: 15391 | I18: 17417.3 | K18: =I22 -> 23814.1 | L18: =K22 -> 25316.728 | M18: =L22 -> 26646.555 | N18: =M22 -> 27823.451 | O18: =N22 -> 28865.004 | P18: =O22 -> 29786.779 | Q18: =P22 -> 30602.549 | R18: =Q22 -> 31325.448 | S18: =R22 -> 31966.157 | T18: =S22 -> 32534.126
B19: Additions | D19: 3313.7 | E19: 6185.4 | F19: 3262.7 | G19: 2945.9 | H19: 4663.5 | I19: 9151.4 | K19: 4500 | L19: 4500 | M19: 4500 | N19: 4500 | O19: 4500 | P19: 4500 | Q19: 4501 | R19: 4502 | S19: 4503 | T19: 4504
B20: Ammortizarion | D20: -1097 | E20: -1427 | F20: -1777.9 | G20: -1954.1 | H20: 2352 | I20: 2663 | K20: =(K18+(K19/2))*K23 -> -2997.3715 | L20: =(L18+(L19/2))*L23 -> -3170.1738 | M20: =(M18+(M19/2))*M23 -> -3323.1038 | N20: =(N18+(N19/2))*N23 -> -3458.4469 | O20: =(O18+(O19/2))*O23 -> -3578.2255 | P20: =(P18+(P19/2))*P23 -> -3684.2295 | Q20: =(Q18+(Q19/2))*Q23 -> -3778.1006 | R20: =(R18+(R19/2))*R23 -> -3861.2916 | ... T20: =(T18+(T19/2))*T23 -> -4000.4045
B21: Others | D21: 212.4 | E21: -474.29 | F21: -322.5 | G21: -649.6 | H21: -4989.2 | I21: -5417.6 | K21: 0 | L21: 0 | M21: 0
B22: Closing balance | C22: =BS!C12 -> 7173.3 | D22: =BS!D12 -> 9602.4 | E22: =BS!E12 -> 13886.5 | F22: =BS!F12 -> 15048.8 | G22: =BS!G12 -> 15391 | H22: =BS!H12 -> 17417.3 | I22: =BS!I12 -> 23814.1 | K22: =SUM(K18:K21) -> 25316.728 | L22: =SUM(L18:L21) -> 26646.555 | M22: =SUM(M18:M21) -> 27823.451 | N22: =SUM(N18:N21) -> 28865.004 | O22: =SUM(O18:O21) -> 29786.779 | P22: =SUM(P18:P21) -> 30602.549 | Q22: =SUM(Q18:Q21) -> 31325.448 | R22: =SUM(R18:R21) -> 31966.157 | ... T22: =SUM(T18:T21) -> 33037.722
B23: Amortization rate | D23: =D20/((D19/2)+D18) -> -0.12423345 | E23: =E20/((E19/2)+E18) -> -0.11240557 | F23: =F20/((F19/2)+F18) -> -0.11457128 | G23: =G20/((G19/2)+G18) -> -0.1182744 | H23: =H20/((H19/2)+H18) -> 0.13271078 | I23: =I20/((I19/2)+I18) -> 0.12108398 | K23: -0.115 | L23: -0.115 | M23: -0.115 | N23: -0.115 | O23: -0.115 | P23: -0.115 | Q23: -0.115 | R23: -0.115 | S23: -0.115 | T23: -0.115
B25: Capital work in progress:
B26: Opening Balance | C26: 3768.4 | D26: 3644 | E26: 10195.9 | F26: 11293.4 | G26: 8291.6 | H26: 9352.2 | I26: 10995.5 | K26: =I29 -> 12999.6 | L26: =K29 -> 29094.783 | M26: =L29 -> 30842.567 | N26: =M29 -> 30741.984 | O26: =N29 -> 30052.781 | P26: =O29 -> 28716.946 | Q26: =P29 -> 26675.617 | R26: =Q29 -> 23869.065 | S26: =R29 -> 20236.692 | T26: =S29 -> 15717.011
B27: Additions during the year | C27: 7291.2 | D27: 11006.7 | E27: 12853.8 | F27: 10890.6 | G27: 11434.6 | H27: 12972.4 | I27: 16835.4 | K27: =K13*K14 -> 32500 | L27: =L13*L14 -> 35000 | M27: =M13*M14 -> 37500 | N27: =N13*N14 -> 40000 | O27: =O13*O14 -> 42500 | P27: =P13*P14 -> 45000 | Q27: =Q13*Q14 -> 47500 | R27: =R13*R14 -> 50000 | ... T27: =T13*T14 -> 55000
B28: Transfer / Adjustment during the year | C28: -7415.6 | D28: -4454.8 | E28: -11756.3 | F28: -13892.4 | G28: -10374 | H28: -11331.1 | I28: -14829.3 | K28: =-I27*K30 -> -16404.817 | L28: =-K27*L30 -> -33252.217 | M28: =-L27*M30 -> -37600.583 | N28: =-M27*N30 -> -40689.203 | O28: =-N27*O30 -> -43835.834 | P28: =-O27*P30 -> -47041.33 | Q28: =-P27*Q30 -> -50306.551 | R28: =-Q27*R30 -> -53632.373 | S28: =-R27*S30 -> -57019.681 | T28: =-S27*T30 -> -60469.372
B29: Closing Balance | C29: 3644 | D29: 10195.9 | E29: 11293.4 | F29: 8291.6 | G29: 9352.2 | H29: 10993.5 | I29: 12999.6 | K29: =SUM(K26:K28) -> 29094.783 | L29: =SUM(L26:L28) -> 30842.567 | M29: =SUM(M26:M28) -> 30741.984 | N29: =SUM(N26:N28) -> 30052.781 | O29: =SUM(O26:O28) -> 28716.946 | P29: =SUM(P26:P28) -> 26675.617 | Q29: =SUM(Q26:Q28) -> 23869.065 | R29: =SUM(R26:R28) -> 20236.692 | ... T29: =SUM(T26:T28) -> 10247.639
B30: Transfer of CWIP as percentage of previosu year's additions | C30: 0 | D30: =-D28/C27 -> 0.6109831 | E30: =-E28/D27 -> 1.068104 | F30: =-F28/E27 -> 1.080801 | G30: =-G28/F27 -> 0.9525646 | H30: =-H28/G27 -> 0.99094852 | I30: =-I28/H27 -> 1.1431424 | K30: =INDEX($K$73:$P$75,MATCH(BS!$D$5,$B$73:$B$75,0),MATCH(K$4,$K$4:$P$4,0)) -> 0.97442393 | L30: =INDEX($K$73:$P$75,MATCH(BS!$D$5,$B$73:$B$75,0),MATCH(L$4,$K$4:$P$4,0)) -> 1.0231451 | M30: =INDEX($K$73:$P$75,MATCH(BS!$D$5,$B$73:$B$75,0),MATCH(M$4,$K$4:$P$4,0)) -> 1.0743024 | N30: =INDEX($K$73:$P$75,MATCH(BS!$D$5,$B$73:$B$75,0),MATCH(N$4,$K$4:$P$4,0)) -> 1.0850454 | O30: =INDEX($K$73:$P$75,MATCH(BS!$D$5,$B$73:$B$75,0),MATCH(O$4,$K$4:$P$4,0)) -> 1.0958959 | P30: =INDEX($K$73:$P$75,MATCH(BS!$D$5,$B$73:$B$75,0),MATCH(P$4,$K$4:$P$4,0)) -> 1.1068548 | Q30: =INDEX($K$73:$T$75,MATCH(BS!$D$5,$B$73:$B$75,0),MATCH(Q$4,$K$4:$T$4,0)) -> 1.1179234 | R30: =INDEX($K$73:$T$75,MATCH(BS!$D$5,$B$73:$B$75,0),MATCH(R$4,$K$4:$T$4,0)) -> 1.1291026 | S30: =INDEX($K$73:$T$75,MATCH(BS!$D$5,$B$73:$B$75,0),MATCH(S$4,$K$4:$T$4,0)) -> 1.1403936 | T30: =INDEX($K$73:$T$75,MATCH(BS!$D$5,$B$73:$B$75,0),MATCH(T$4,$K$4:$T$4,0)) -> 1.1517976
B32: Lease Liabilities:
B33: Current lease | C33: =BS!C54 -> 743.5 | D33: =BS!D54 -> 807 | E33: =BS!E54 -> 1397.9 | F33: =BS!F54 -> 1663.2 | G33: =BS!G54 -> 1929.2 | H33: =BS!H54 -> 2638.3 | I33: =BS!I54 -> 3171.8 | K33: =K36*K35 -> 4087.9538 | L33: =L36*L35 -> 4193.7236 | M33: =M36*M35 -> 4272.3429 | N33: =N36*N35 -> 4330.7811 | O33: =O36*O35 -> 4374.2186 | P33: =P36*P35 -> 4406.5059 | Q33: =Q36*Q35 -> 4430.762 | R33: =R36*R35 -> 4449.0483 | ... T33: =T36*T35 -> 4473.4482
B34: Non-current lease | C34: =BS!C46 -> 2211.1 | D34: =BS!D46 -> 3120.1 | E34: =BS!E46 -> 5071.5 | F34: =BS!F46 -> 4766.6 | G34: =BS!G46 -> 3992.4 | H34: =BS!H46 -> 5557.9 | I34: =BS!I46 -> 11425.4 | K34: =K35-K33 -> 11837.446 | L34: =L35-L33 -> 12143.723 | M34: =M35-M33 -> 12371.38 | N34: =N35-N33 -> 12540.599 | O34: =O35-O33 -> 12666.38 | P34: =P35-P33 -> 12759.874 | Q34: =Q35-Q33 -> 12830.112 | R34: =R35-R33 -> 12883.064 | ... T34: =T35-T33 -> 12953.718
B35: Total | C35: =SUM(C33:C34) -> 2954.6 | D35: =SUM(D33:D34) -> 3927.1 | E35: =SUM(E33:E34) -> 6469.4 | F35: =SUM(F33:F34) -> 6429.8 | G35: =SUM(G33:G34) -> 5921.6 | H35: =SUM(H33:H34) -> 8196.2 | I35: =SUM(I33:I34) -> 14597.2 | K35: =K41 -> 15925.4 | L35: =L41 -> 16337.446 | M35: =M41 -> 16643.723 | N35: =N41 -> 16871.38 | O35: =O41 -> 17040.599 | P35: =P41 -> 17166.38 | Q35: =Q41 -> 17260.874 | R35: =R41 -> 17332.112 | ... T35: =T41 -> 17427.167
B36: Current lease as a % of total | C36: =C33/C35 -> 0.25164151 | D36: =D33/D35 -> 0.20549515 | E36: =E33/E35 -> 0.21607877 | F36: =F33/F35 -> 0.25867057 | G36: =G33/G35 -> 0.32579033 | H36: =H33/H35 -> 0.32189307 | I36: =I33/I35 -> 0.21728825 | K36: =AVERAGE($C$36:$I$36) -> 0.25669395 | L36: =AVERAGE($C$36:$I$36) -> 0.25669395 | M36: =AVERAGE($C$36:$I$36) -> 0.25669395 | N36: =AVERAGE($C$36:$I$36) -> 0.25669395 | O36: =AVERAGE($C$36:$I$36) -> 0.25669395 | P36: =AVERAGE($C$36:$I$36) -> 0.25669395 | Q36: =AVERAGE($C$36:$I$36) -> 0.25669395 | R36: =AVERAGE($C$36:$I$36) -> 0.25669395 | ... T36: =AVERAGE($C$36:$I$36) -> 0.25669395
B38: Opening balance | K38: =I41 -> 14597.2 | L38: =K41 -> 15925.4 | M38: =L41 -> 16337.446 | N38: =M41 -> 16643.723 | O38: =N41 -> 16871.38 | P38: =O41 -> 17040.599 | Q38: =P41 -> 17166.38 | R38: =Q41 -> 17260.874 | S38: =R41 -> 17332.112 | T38: =S41 -> 17386.064
B39: Additions | K39: =K19 -> 4500 | L39: =L19 -> 4500 | M39: =M19 -> 4500 | N39: =N19 -> 4500 | O39: =O19 -> 4500 | P39: =P19 -> 4500 | Q39: =Q19 -> 4501 | R39: =R19 -> 4502 | ... T39: =T19 -> 4504
B40: Repayments | K40: =-I33 -> -3171.8 | L40: =-K33 -> -4087.9538 | M40: =-L33 -> -4193.7236 | N40: =-M33 -> -4272.3429 | O40: =-N33 -> -4330.7811 | P40: =-O33 -> -4374.2186 | Q40: =-P33 -> -4406.5059 | R40: =-Q33 -> -4430.762 | S40: =-R33 -> -4449.0483 | T40: =-S33 -> -4462.8974
B41: Closing balance | I41: =I35 -> 14597.2 | K41: =SUM(K38:K40) -> 15925.4 | L41: =SUM(L38:L40) -> 16337.446 | M41: =SUM(M38:M40) -> 16643.723 | N41: =SUM(N38:N40) -> 16871.38 | O41: =SUM(O38:O40) -> 17040.599 | P41: =SUM(P38:P40) -> 17166.38 | Q41: =SUM(Q38:Q40) -> 17260.874 | R41: =SUM(R38:R40) -> 17332.112 | ... T41: =SUM(T38:T40) -> 17427.167
B43: Deferred tax liability on account of:
B44: Depreciation | C44: 555 | D44: 656.5 | E44: 826.7 | F44: 1036.9 | G44: 1297.9 | H44: 1537.4 | I44: 1871.8 | K44: =K58*BS!K10 -> 1977.5917 | L44: =L58*BS!L10 -> 2228.9338 | M44: =M58*BS!M10 -> 2513.5069 | N44: =N58*BS!N10 -> 2816.3816 | O44: =O58*BS!O10 -> 3137.2538 | P44: =P58*BS!P10 -> 3475.8435 | Q44: =Q58*BS!Q10 -> 3831.8939 | R44: =R58*BS!R10 -> 4205.1704 | ... T44: =T58*BS!T10 -> 5002.5664
B45: Employee benefits | C45: 0 | D45: 0 | E45: 0 | F45: 0 | G45: 0 | H45: 0 | I45: 0 | K45: 0 | L45: 0 | M45: 0 | N45: 0 | O45: 0 | P45: 0 | Q45: 0 | R45: 0 | S45: 0 | T45: 0
B46: Right-of-use asset | C46: 0 | D46: 0 | E46: 0 | F46: 0 | G46: 996.6 | H46: 1550.2 | I46: 3023.2 | K46: 0 | L46: 0 | M46: 0 | N46: 0 | O46: 0 | P46: 0 | Q46: 0 | R46: 0 | S46: 0 | T46: 0
B47: Unrealised profit on cosolidation | C47: 0 | D47: 0 | E47: 0 | F47: 0 | G47: 0 | H47: 0 | I47: 0 | K47: 0 | L47: 0 | M47: 0 | N47: 0 | O47: 0 | P47: 0 | Q47: 0 | R47: 0 | S47: 0 | T47: 0
B48: Fair value gain on financial instruments at Fair value through statement of profit and loss | C48: 1.4 | D48: 0 | E48: 0 | F48: 0 | G48: 0 | H48: 0 | I48: 0 | K48: 0 | L48: 0 | M48: 0 | N48: 0 | O48: 0 | P48: 0 | Q48: 0 | R48: 0 | S48: 0 | T48: 0
B49: Others | C49: 0 | D49: 0 | E49: 0 | F49: 8 | G49: 0.9 | H49: 0 | I49: 0 | K49: 0 | L49: 0 | M49: 0 | N49: 0 | O49: 0 | P49: 0 | Q49: 0 | R49: 0 | S49: 0 | T49: 0
...

Sheet Data_Sheet
A1: Date | B1: Price | C1: Open | D1: High | E1: Low | F1: Vol. | G1: Change % | H1: Year | I1: Quarter | J1: Month | P1: 2020-21 | Q1: 2021-22 | R1: 2022-23 | S1: 2023-24 | T1: 2024-25 | U1: 2025-26
A2: 43922 | B2: 2082.7 | C2: 2218 | D2: 2230 | E2: 2078.15 | F2: 272200 | G2: -0.0479 | H2: =YEAR(AVEU_Historical_Data__2[[#This Row],[Date]]) -> 2020 | I2: =ROUNDUP((MOD(MONTH(AVEU_Historical_Data__2[[#This Row],[Date]])+8,12)+1)/3,0) -> 1 | J2: =MONTH(AVEU_Historical_Data__2[[#This Row],[Date]]) -> 4 | O2: Revenue growth (Y-o-Y) | P2: -0.029237401 | Q2: 0.28302999 | R2: 0.38297994 | S2: 0.1855591 | T2: 0.16872253 | U2: 0.15941713
A3: 43924 | B3: 2066.95 | C3: 2101.5 | D3: 2119 | E3: 2020 | F3: 303210 | G3: -0.0076 | H3: =YEAR(AVEU_Historical_Data__2[[#This Row],[Date]]) -> 2020 | I3: =ROUNDUP((MOD(MONTH(AVEU_Historical_Data__2[[#This Row],[Date]])+8,12)+1)/3,0) -> 1 | J3: =MONTH(AVEU_Historical_Data__2[[#This Row],[Date]]) -> 4 | L3: Row Labels | M3: Average of Price
A4: 43928 | B4: 2170.25 | C4: 2090.1 | D4: 2170.25 | E4: 2090.1 | F4: 219470 | G4: 0.05 | H4: =YEAR(AVEU_Historical_Data__2[[#This Row],[Date]]) -> 2020 | I4: =ROUNDUP((MOD(MONTH(AVEU_Historical_Data__2[[#This Row],[Date]])+8,12)+1)/3,0) -> 1 | J4: =MONTH(AVEU_Historical_Data__2[[#This Row],[Date]]) -> 4 | L4: 2020 | M4: 2280.6283 | P4: 2020-21 | Q4: 2021-22 | R4: 2022-23 | S4: 2023-24 | T4: 2024-25 | U4: 2025-26
A5: 43929 | B5: 2278.75 | C5: 2222 | D5: 2278.75 | E5: 2201.05 | F5: 153350 | G5: 0.05 | H5: =YEAR(AVEU_Historical_Data__2[[#This Row],[Date]]) -> 2020 | I5: =ROUNDUP((MOD(MONTH(AVEU_Historical_Data__2[[#This Row],[Date]])+8,12)+1)/3,0) -> 1 | J5: =MONTH(AVEU_Historical_Data__2[[#This Row],[Date]]) -> 4 | L5: 2021 | M5: 3620.9115 | O5: Revenue from sales from per retail sales area sq.ft | P5: 27306 | Q5: 27454 | R5: 31096 | S5: 32941 | T5: 33869 | U5: 33422
A6: 43930 | B6: 2392.65 | C6: 2392.65 | D6: 2392.65 | E6: 2392.65 | F6: 231680 | G6: 0.05 | H6: =YEAR(AVEU_Historical_Data__2[[#This Row],[Date]]) -> 2020 | I6: =ROUNDUP((MOD(MONTH(AVEU_Historical_Data__2[[#This Row],[Date]])+8,12)+1)/3,0) -> 1 | J6: =MONTH(AVEU_Historical_Data__2[[#This Row],[Date]]) -> 4 | L6: 2022 | M6: 4077.6554
A7: 43934 | B7: 2273.05 | C7: 2320 | D7: 2320 | E7: 2273.05 | F7: 272320 | G7: -0.05 | H7: =YEAR(AVEU_Historical_Data__2[[#This Row],[Date]]) -> 2020 | I7: =ROUNDUP((MOD(MONTH(AVEU_Historical_Data__2[[#This Row],[Date]])+8,12)+1)/3,0) -> 1 | J7: =MONTH(AVEU_Historical_Data__2[[#This Row],[Date]]) -> 4 | L7: 2023 | M7: 3673.7089 | P7: 2020-21 | Q7: 2021-22 | R7: 2022-23 | S7: 2023-24 | T7: 2024-25 | U7: 2025-26
A8: 43936 | B8: 2180.9 | C8: 2161 | D8: 2320 | E8: 2159.4 | F8: 634860 | G8: -0.0405 | H8: =YEAR(AVEU_Historical_Data__2[[#This Row],[Date]]) -> 2020 | I8: =ROUNDUP((MOD(MONTH(AVEU_Historical_Data__2[[#This Row],[Date]])+8,12)+1)/3,0) -> 1 | J8: =MONTH(AVEU_Historical_Data__2[[#This Row],[Date]]) -> 4 | L8: 2024 | M8: 4383.2404 | O8: Retail sales area | P8: 8.8 | Q8: 11.5 | R8: 13.4 | S8: 15.1 | T8: 17.2 | U8: 20.6
A9: 43937 | B9: 2137.85 | C9: 2151 | D9: 2210 | E9: 2104.9 | F9: 393230 | G9: -0.0197 | H9: =YEAR(AVEU_Historical_Data__2[[#This Row],[Date]]) -> 2020 | I9: =ROUNDUP((MOD(MONTH(AVEU_Historical_Data__2[[#This Row],[Date]])+8,12)+1)/3,0) -> 1 | J9: =MONTH(AVEU_Historical_Data__2[[#This Row],[Date]]) -> 4 | L9: 2025 | M9: 4083.3016
A10: 43938 | B10: 2212.1 | C10: 2214 | D10: 2230 | E10: 2200 | F10: 292020 | G10: 0.0347 | H10: =YEAR(AVEU_Historical_Data__2[[#This Row],[Date]]) -> 2020 | I10: =ROUNDUP((MOD(MONTH(AVEU_Historical_Data__2[[#This Row],[Date]])+8,12)+1)/3,0) -> 1 | J10: =MONTH(AVEU_Historical_Data__2[[#This Row],[Date]]) -> 4 | L10: 2026 | M10: 4041.9933 | P10: 2020-21 | Q10: 2021-22 | R10: 2022-23 | S10: 2023-24 | T10: 2024-25 | U10: 2025-26
A11: 43941 | B11: 2256.25 | C11: 2229.95 | D11: 2285 | E11: 2150.05 | F11: 274760 | G11: 0.02 | H11: =YEAR(AVEU_Historical_Data__2[[#This Row],[Date]]) -> 2020 | I11: =ROUNDUP((MOD(MONTH(AVEU_Historical_Data__2[[#This Row],[Date]])+8,12)+1)/3,0) -> 1 | J11: =MONTH(AVEU_Historical_Data__2[[#This Row],[Date]]) -> 4 | L11: Grand Total | M11: 3777.9851 | O11: Revenue from operations | P11: 241430.6 | Q11: 309762.7 | R11: 428395.6 | S11: 507888.3 | T11: 593580.5 | U11: 688207.4
A12: 43942 | B12: 2238.2 | C12: 2200 | D12: 2288.5 | E12: 2199.45 | F12: 205880 | G12: -0.008 | H12: =YEAR(AVEU_Historical_Data__2[[#This Row],[Date]]) -> 2020 | I12: =ROUNDUP((MOD(MONTH(AVEU_Historical_Data__2[[#This Row],[Date]])+8,12)+1)/3,0) -> 1 | J12: =MONTH(AVEU_Historical_Data__2[[#This Row],[Date]]) -> 4
A13: 43943 | B13: 2290.05 | C13: 2235 | D13: 2320 | E13: 2225 | F13: 232000 | G13: 0.0232 | H13: =YEAR(AVEU_Historical_Data__2[[#This Row],[Date]]) -> 2020 | I13: =ROUNDUP((MOD(MONTH(AVEU_Historical_Data__2[[#This Row],[Date]])+8,12)+1)/3,0) -> 1 | J13: =MONTH(AVEU_Historical_Data__2[[#This Row],[Date]]) -> 4 | P13: 2020-21 | Q13: 2021-22 | R13: 2022-23 | S13: 2023-24 | T13: 2024-25 | U13: 2025-26
A14: 43944 | B14: 2303.5 | C14: 2290.05 | D14: 2350 | E14: 2290.05 | F14: 182400 | G14: 0.0059 | H14: =YEAR(AVEU_Historical_Data__2[[#This Row],[Date]]) -> 2020 | I14: =ROUNDUP((MOD(MONTH(AVEU_Historical_Data__2[[#This Row],[Date]])+8,12)+1)/3,0) -> 1 | J14: =MONTH(AVEU_Historical_Data__2[[#This Row],[Date]]) -> 4 | L14: Row Labels | M14: Sum of Volume | O14: EBIT | P14: 13288.9 | Q14: 20004.2 | R14: 29981.6 | S14: 33730.1 | T14: 36178.1 | U14: 41495.7
A15: 43945 | B15: 2310.5 | C15: 2299.45 | D15: 2346.5 | E15: 2269.45 | F15: 586420 | G15: 0.003 | H15: =YEAR(AVEU_Historical_Data__2[[#This Row],[Date]]) -> 2020 | I15: =ROUNDUP((MOD(MONTH(AVEU_Historical_Data__2[[#This Row],[Date]])+8,12)+1)/3,0) -> 1 | J15: =MONTH(AVEU_Historical_Data__2[[#This Row],[Date]]) -> 4 | L15: 2020 | M15: 119713620 | O15: EBIT margin | P15: 0.055042319 | Q15: 0.064579112 | R15: 0.069985779 | S15: 0.066412438 | T15: 0.060948936 | U15: 0.060295341
A16: 43948 | B16: 2323.95 | C16: 2300 | D16: 2350 | E16: 2274 | F16: 198320 | G16: 0.0058 | H16: =YEAR(AVEU_Historical_Data__2[[#This Row],[Date]]) -> 2020 | I16: =ROUNDUP((MOD(MONTH(AVEU_Historical_Data__2[[#This Row],[Date]])+8,12)+1)/3,0) -> 1 | J16: =MONTH(AVEU_Historical_Data__2[[#This Row],[Date]]) -> 4 | L16: 2021 | M16: 116165280
A17: 43949 | B17: 2305.8 | C17: 2339 | D17: 2340 | E17: 2285 | F17: 858550 | G17: -0.0078 | H17: =YEAR(AVEU_Historical_Data__2[[#This Row],[Date]]) -> 2020 | I17: =ROUNDUP((MOD(MONTH(AVEU_Historical_Data__2[[#This Row],[Date]])+8,12)+1)/3,0) -> 1 | J17: =MONTH(AVEU_Historical_Data__2[[#This Row],[Date]]) -> 4 | L17: 2022 | M17: 102609300 | P17: 2020-21 | Q17: 2021-22 | R17: 2022-23 | S17: 2023-24 | T17: 2024-25 | U17: 2025-26
A18: 43950 | B18: 2344.35 | C18: 2310 | D18: 2350 | E18: 2305.8 | F18: 120880 | G18: 0.0167 | H18: =YEAR(AVEU_Historical_Data__2[[#This Row],[Date]]) -> 2020 | I18: =ROUNDUP((MOD(MONTH(AVEU_Historical_Data__2[[#This Row],[Date]])+8,12)+1)/3,0) -> 1 | J18: =MONTH(AVEU_Historical_Data__2[[#This Row],[Date]]) -> 4 | L18: 2023 | M18: 85452980 | O18: Net Profit | P18: 10994.3 | Q18: 14924 | R18: 23783.4 | S18: 25356.1 | T18: 27074.5 | U18: 29706
A19: 43951 | B19: 2383.65 | C19: 2349 | D19: 2389.75 | E19: 2325 | F19: 619340 | G19: 0.0168 | H19: =YEAR(AVEU_Historical_Data__2[[#This Row],[Date]]) -> 2020 | I19: =ROUNDUP((MOD(MONTH(AVEU_Historical_Data__2[[#This Row],[Date]])+8,12)+1)/3,0) -> 1 | J19: =MONTH(AVEU_Historical_Data__2[[#This Row],[Date]]) -> 4 | L19: 2024 | M19: 138939140 | O19: Net profit margin | P19: 0.045538138 | Q19: 0.048178816 | R19: 0.055517377 | S19: 0.04992456 | T19: 0.045612179 | U19: 0.043164314
A20: 43955 | B20: 2281.3 | C20: 2310.2 | D20: 2345 | E20: 2269.95 | F20: 234630 | G20: -0.0429 | H20: =YEAR(AVEU_Historical_Data__2[[#This Row],[Date]]) -> 2020 | I20: =ROUNDUP((MOD(MONTH(AVEU_Historical_Data__2[[#This Row],[Date]])+8,12)+1)/3,0) -> 1 | J20: =MONTH(AVEU_Historical_Data__2[[#This Row],[Date]]) -> 5 | L20: 2025 | M20: 145453260
A21: 43956 | B21: 2198.95 | C21: 2320 | D21: 2329.95 | E21: 2185.3 | F21: 183050 | G21: -0.0361 | H21: =YEAR(AVEU_Historical_Data__2[[#This Row],[Date]]) -> 2020 | I21: =ROUNDUP((MOD(MONTH(AVEU_Historical_Data__2[[#This Row],[Date]])+8,12)+1)/3,0) -> 1 | J21: =MONTH(AVEU_Historical_Data__2[[#This Row],[Date]]) -> 5 | L21: 2026 | M21: 93491040 | P21: 2020-21 | Q21: 2021-22 | R21: 2022-23 | S21: 2023-24 | T21: 2024-25 | U21: 2025-26
A22: 43957 | B22: 2175.6 | C22: 2200 | D22: 2249 | E22: 2126.55 | F22: 292520 | G22: -0.0106 | H22: =YEAR(AVEU_Historical_Data__2[[#This Row],[Date]]) -> 2020 | I22: =ROUNDUP((MOD(MONTH(AVEU_Historical_Data__2[[#This Row],[Date]])+8,12)+1)/3,0) -> 1 | J22: =MONTH(AVEU_Historical_Data__2[[#This Row],[Date]]) -> 5 | L22: Grand Total | M22: 801824620 | O22: Net cash flow from operating activities | P22: 13751.4 | Q22: 13723.5 | R22: 26302.7 | S22: 27458.4 | T22: 24629.7 | U22: 34667.4
A23: 43958 | B23: 2182.1 | C23: 2180 | D23: 2210.3 | E23: 2144 | F23: 287440 | G23: 0.003 | H23: =YEAR(AVEU_Historical_Data__2[[#This Row],[Date]]) -> 2020 | I23: =ROUNDUP((MOD(MONTH(AVEU_Historical_Data__2[[#This Row],[Date]])+8,12)+1)/3,0) -> 1 | J23: =MONTH(AVEU_Historical_Data__2[[#This Row],[Date]]) -> 5
A24: 43959 | B24: 2255 | C24: 2190 | D24: 2284 | E24: 2185 | F24: 247820 | G24: 0.0334 | H24: =YEAR(AVEU_Historical_Data__2[[#This Row],[Date]]) -> 2020 | I24: =ROUNDUP((MOD(MONTH(AVEU_Historical_Data__2[[#This Row],[Date]])+8,12)+1)/3,0) -> 1 | J24: =MONTH(AVEU_Historical_Data__2[[#This Row],[Date]]) -> 5 | P24: 2020-21 | Q24: 2021-22 | R24: 2022-23 | S24: 2023-24 | T24: 2024-25 | U24: 2025-26
A25: 43962 | B25: 2313.55 | C25: 2280 | D25: 2358 | E25: 2270 | F25: 279520 | G25: 0.026 | H25: =YEAR(AVEU_Historical_Data__2[[#This Row],[Date]]) -> 2020 | I25: =ROUNDUP((MOD(MONTH(AVEU_Historical_Data__2[[#This Row],[Date]])+8,12)+1)/3,0) -> 1 | J25: =MONTH(AVEU_Historical_Data__2[[#This Row],[Date]]) -> 5 | L25: Top shareholders | M25: Shareholding % | O25: No.of days in inventory | P25: 37.252421 | Q25: 34.505175 | R25: 30.10843 | S25: 30.241088 | T25: 32.389249 | U25: 34.16821
A26: 43963 | B26: 2303.35 | C26: 2320.55 | D26: 2347 | E26: 2286.9 | F26: 277810 | G26: -0.0044 | H26: =YEAR(AVEU_Historical_Data__2[[#This Row],[Date]]) -> 2020 | I26: =ROUNDUP((MOD(MONTH(AVEU_Historical_Data__2[[#This Row],[Date]])+8,12)+1)/3,0) -> 1 | J26: =MONTH(AVEU_Historical_Data__2[[#This Row],[Date]]) -> 5 | L26: Promoter | M26: 0.7452 | O26: No.of days for receivables | P26: 0.47720649 | Q26: 0.65084579 | R26: 0.55126967 | S26: 0.82117909 | T26: 0.98435174 | U26: 0.80384525
A27: 43964 | B27: 2352.15 | C27: 2353 | D27: 2379.95 | E27: 2305 | F27: 373230 | G27: 0.0212 | H27: =YEAR(AVEU_Historical_Data__2[[#This Row],[Date]]) -> 2020 | I27: =ROUNDUP((MOD(MONTH(AVEU_Historical_Data__2[[#This Row],[Date]])+8,12)+1)/3,0) -> 1 | J27: =MONTH(AVEU_Historical_Data__2[[#This Row],[Date]]) -> 5 | L27: Mutual Funds | M27: 0.0677 | O27: No.of days for payables | P27: 8.9815726 | Q27: 8.0704087 | R27: 6.7548238 | S27: 7.3321288 | T27: 7.4211283 | U27: 7.5205582
A28: 43965 | B28: 2324.4 | C28: 2344.35 | D28: 2358 | E28: 2304 | F28: 344410 | G28: -0.0118 | H28: =YEAR(AVEU_Historical_Data__2[[#This Row],[Date]]) -> 2020 | I28: =ROUNDUP((MOD(MONTH(AVEU_Historical_Data__2[[#This Row],[Date]])+8,12)+1)/3,0) -> 1 | J28: =MONTH(AVEU_Historical_Data__2[[#This Row],[Date]]) -> 5 | L28: Foreign Portfolio Investor | M28: 0.09 | O28: Cash Conversion Cycle | P28: =P25+P26-P27 -> 28.748055 | Q28: =Q25+Q26-Q27 -> 27.085612 | R28: =R25+R26-R27 -> 23.904876 | S28: =S25+S26-S27 -> 23.730138 | T28: =T25+T26-T27 -> 25.952472 | U28: =U25+U26-U27 -> 27.451497
A29: 43966 | B29: 2333.8 | C29: 2320 | D29: 2340 | E29: 2290.25 | F29: 181710 | G29: 0.004 | H29: =YEAR(AVEU_Historical_Data__2[[#This Row],[Date]]) -> 2020 | I29: =ROUNDUP((MOD(MONTH(AVEU_Historical_Data__2[[#This Row],[Date]])+8,12)+1)/3,0) -> 1 | J29: =MONTH(AVEU_Historical_Data__2[[#This Row],[Date]]) -> 5 | L29: Provident Funds/Pension Funds | M29: 0.0146
A30: 43969 | B30: 2306.55 | C30: 2333 | D30: 2370.8 | E30: 2275 | F30: 293740 | G30: -0.0117 | H30: =YEAR(AVEU_Historical_Data__2[[#This Row],[Date]]) -> 2020 | I30: =ROUNDUP((MOD(MONTH(AVEU_Historical_Data__2[[#This Row],[Date]])+8,12)+1)/3,0) -> 1 | J30: =MONTH(AVEU_Historical_Data__2[[#This Row],[Date]]) -> 5 | L30: Individuals | M30: 0.0719 | P30: 2020-21 | Q30: 2021-22 | R30: 2022-23 | S30: 2023-24 | T30: 2024-25 | U30: 2025-26
A31: 43970 | B31: 2337.5 | C31: 2341.95 | D31: 2355.6 | E31: 2306 | F31: 254060 | G31: 0.0134 | H31: =YEAR(AVEU_Historical_Data__2[[#This Row],[Date]]) -> 2020 | I31: =ROUNDUP((MOD(MONTH(AVEU_Historical_Data__2[[#This Row],[Date]])+8,12)+1)/3,0) -> 1 | J31: =MONTH(AVEU_Historical_Data__2[[#This Row],[Date]]) -> 5 | L31: Minority Shareholders | M31: 0.0106 | O31: Equity | P31: 121841.1 | Q31: 136778.9 | R31: 160787.8 | S31: 186973.4 | T31: 214267 | U31: 244623.6
A32: 43971 | B32: 2454.35 | C32: 2335 | D32: 2454.35 | E32: 2318 | F32: 374840 | G32: 0.05 | H32: =YEAR(AVEU_Historical_Data__2[[#This Row],[Date]]) -> 2020 | I32: =ROUNDUP((MOD(MONTH(AVEU_Historical_Data__2[[#This Row],[Date]])+8,12)+1)/3,0) -> 1 | J32: =MONTH(AVEU_Historical_Data__2[[#This Row],[Date]]) -> 5 | L32: Total (A+B) | M32: =SUM(M26:M31) -> 1 | O32: Debt | P32: =SUM(BS!D46:D47,BS!D53:D54,BS!D56:D58,BS!D59) -> 13537.2 | Q32: =SUM(BS!E46:E47,BS!E53:E54,BS!E56:E58,BS!E59) -> 16310.4 | R32: =SUM(BS!F46:F47,BS!F53:F54,BS!F56:F58,BS!F59) -> 18078.8 | S32: =SUM(BS!G46:G47,BS!G53:G54,BS!G56:G58,BS!G59) -> 20629.3 | T32: =SUM(BS!H46:H47,BS!H53:H54,BS!H56:H58,BS!H59) -> 24781.8 | U32: =SUM(BS!I46:I47,BS!I53:I54,BS!I56:I58,BS!I59) -> 45423.9
A33: 43972 | B33: 2470.25 | C33: 2452 | D33: 2519.95 | E33: 2375 | F33: 359120 | G33: 0.0065 | H33: =YEAR(AVEU_Historical_Data__2[[#This Row],[Date]]) -> 2020 | I33: =ROUNDUP((MOD(MONTH(AVEU_Historical_Data__2[[#This Row],[Date]])+8,12)+1)/3,0) -> 1 | J33: =MONTH(AVEU_Historical_Data__2[[#This Row],[Date]]) -> 5 | O33: Debt to equity ratio | P33: =P32/P31 -> 0.11110537 | Q33: =Q32/Q31 -> 0.11924646 | R33: =R32/R31 -> 0.11243888 | S33: =S32/S31 -> 0.11033281 | T33: =T32/T31 -> 0.1156585 | U33: =U32/U31 -> 0.18568895
A34: 43973 | B34: 2398.3 | C34: 2484.8 | D34: 2518 | E34: 2381.5 | F34: 388440 | G34: -0.0291 | H34: =YEAR(AVEU_Historical_Data__2[[#This Row],[Date]]) -> 2020 | I34: =ROUNDUP((MOD(MONTH(AVEU_Historical_Data__2[[#This Row],[Date]])+8,12)+1)/3,0) -> 1 | J34: =MONTH(AVEU_Historical_Data__2[[#This Row],[Date]]) -> 5
A35: 43977 | B35: 2283.25 | C35: 2339 | D35: 2340 | E35: 2278.4 | F35: 773060 | G35: -0.048 | H35: =YEAR(AVEU_Historical_Data__2[[#This Row],[Date]]) -> 2020 | I35: =ROUNDUP((MOD(MONTH(AVEU_Historical_Data__2[[#This Row],[Date]])+8,12)+1)/3,0) -> 1 | J35: =MONTH(AVEU_Historical_Data__2[[#This Row],[Date]]) -> 5 | P35: 2020-21 | Q35: 2021-22 | R35: 2022-23 | S35: 2023-24 | T35: 2024-25 | U35: 2025-26
A36: 43978 | B36: 2200.2 | C36: 2222.2 | D36: 2275 | E36: 2176 | F36: 751860 | G36: -0.0364 | H36: =YEAR(AVEU_Historical_Data__2[[#This Row],[Date]]) -> 2020 | I36: =ROUNDUP((MOD(MONTH(AVEU_Historical_Data__2[[#This Row],[Date]])+8,12)+1)/3,0) -> 1 | J36: =MONTH(AVEU_Historical_Data__2[[#This Row],[Date]]) -> 5 | O36: Net profit after tax | P36: ='P & L'!D32 -> 10994.3 | Q36: ='P & L'!E32 -> 14924 | R36: ='P & L'!F32 -> 23783.4 | S36: ='P & L'!G32 -> 25356.1 | T36: ='P & L'!H32 -> 27074.5 | U36: ='P & L'!I32 -> 29706
A37: 43979 | B37: 2308.45 | C37: 2210 | D37: 2310.2 | E37: 2205 | F37: 927240 | G37: 0.0492 | H37: =YEAR(AVEU_Historical_Data__2[[#This Row],[Date]]) -> 2020 | I37: =ROUNDUP((MOD(MONTH(AVEU_Historical_Data__2[[#This Row],[Date]])+8,12)+1)/3,0) -> 1 | J37: =MONTH(AVEU_Historical_Data__2[[#This Row],[Date]]) -> 5 | O37: Average net worth | P37: =AVERAGE(BS!C34:D34)-SUM(AVERAGE(BS!C50:D50),AVERAGE(BS!C62:D62)) -> 116321.55 | Q37: =AVERAGE(BS!D34:E34)-SUM(AVERAGE(BS!D50:E50),AVERAGE(BS!D62:E62)) -> 129310 | R37: =AVERAGE(BS!E34:F34)-SUM(AVERAGE(BS!E50:F50),AVERAGE(BS!E62:F62)) -> 148783.35 | S37: =AVERAGE(BS!F34:G34)-SUM(AVERAGE(BS!F50:G50),AVERAGE(BS!F62:G62)) -> 173880.6 | T37: =AVERAGE(BS!G34:H34)-SUM(AVERAGE(BS!G50:H50),AVERAGE(BS!G62:H62)) -> 200620.2 | U37: =AVERAGE(BS!H34:I34)-SUM(AVERAGE(BS!H50:I50),AVERAGE(BS!H62:I62)) -> 229445.3
A38: 43980 | B38: 2269.35 | C38: 2330 | D38: 2358 | E38: 2229 | F38: 3800000 | G38: -0.0169 | H38: =YEAR(AVEU_Historical_Data__2[[#This Row],[Date]]) -> 2020 | I38: =ROUNDUP((MOD(MONTH(AVEU_Historical_Data__2[[#This Row],[Date]])+8,12)+1)/3,0) -> 1 | J38: =MONTH(AVEU_Historical_Data__2[[#This Row],[Date]]) -> 5 | O38: Capital employed | P38: =AVERAGE(P32:P32)+AVERAGE(P31:P31)-AVERAGE(BS!C28:D28)-AVERAGE(BS!C26:D26) -> 133803.3 | Q38: =AVERAGE(P32:Q32)+AVERAGE(P31:Q31)-AVERAGE(BS!D28:E28)-AVERAGE(BS!D26:E26) -> 142756.3 | R38: =AVERAGE(Q32:R32)+AVERAGE(Q31:R31)-AVERAGE(BS!E28:F28)-AVERAGE(BS!E26:F26) -> 163426 | S38: =AVERAGE(R32:S32)+AVERAGE(R31:S31)-AVERAGE(BS!F28:G28)-AVERAGE(BS!F26:G26) -> 188969.05 | T38: =AVERAGE(S32:T32)+AVERAGE(S31:T31)-AVERAGE(BS!G28:H28)-AVERAGE(BS!G26:H26) -> 219323.2 | U38: =AVERAGE(T32:U32)+AVERAGE(T31:U31)-AVERAGE(BS!H28:I28)-AVERAGE(BS!H26:I26) -> 261335.95
A39: 43983 | B39: 2305.5 | C39: 2320.1 | D39: 2328.55 | E39: 2282.65 | F39: 448580 | G39: 0.0159 | H39: =YEAR(AVEU_Historical_Data__2[[#This Row],[Date]]) -> 2020 | I39: =ROUNDUP((MOD(MONTH(AVEU_Historical_Data__2[[#This Row],[Date]])+8,12)+1)/3,0) -> 1 | J39: =MONTH(AVEU_Historical_Data__2[[#This Row],[Date]]) -> 6 | O39: Return on Net Worth | P39: =P$36/P37 -> 0.09451645 | Q39: =Q$36/Q37 -> 0.11541257 | R39: =R$36/R37 -> 0.15985256 | S39: =S$36/S37 -> 0.14582478 | T39: =T$36/T37 -> 0.13495401 | U39: =U$36/U37 -> 0.12946877
A40: 43984 | B40: 2381.7 | C40: 2309.1 | D40: 2389 | E40: 2290.05 | F40: 503210 | G40: 0.0331 | H40: =YEAR(AVEU_Historical_Data__2[[#This Row],[Date]]) -> 2020 | I40: =ROUNDUP((MOD(MONTH(AVEU_Historical_Data__2[[#This Row],[Date]])+8,12)+1)/3,0) -> 1 | J40: =MONTH(AVEU_Historical_Data__2[[#This Row],[Date]]) -> 6 | O40: Return on Capital Employed | P40: =P$36/P38 -> 0.08216763 | Q40: =Q$36/Q38 -> 0.1045418 | R40: =R$36/R38 -> 0.14553009 | S40: =S$36/S38 -> 0.13418123 | T40: =T$36/T38 -> 0.12344567 | U40: =U$36/U38 -> 0.11366978
...

Sheet Front Page
B19: Equity Research Report & Valuation Model
E37: 2026
I42: Prepared by:
J44: Pranesh MK

Sheet Index
B20: TABLE OF CONTENTS
B24: S.No | D24: Titles
B29: 1 | D29: Introduction
B32: 2 | D32: Operating & Financial Summary
B35: 3 | D35: Ratio Analysis
B38: 4 | D38: Profit & Loss Statement
B41: 5 | D41: Profit & Loss Statement
B44: 6 | D44: Balance Sheet
B47: 7 | D47: Cash Flow Statement
B50: 8 | D50: DCF Valuation

Sheet Introduction
B2: Avenue Supermarts Limited - A One Page Financial Profile
F5: Avenue Supermarts Limited is an Indian retail company that operates a chain of supermarkets under the DMart brand. DMart follows a value-retail business model, focusing on offering everyday products at competitive prices while maintaining relatively disciplined operating costs. The company's core business is the retailing of food, FMCG, general merchandise and apparel products through its network of physical stores. DMart's business model is based largely on the Everyday Low Cost/Everyday Low Price philosophy.
B14: Key Financial Metrics:
C17: Key Financial Metrics | D17: 43921 | E17: =EOMONTH(D17,12) -> 44286 | F17: =EOMONTH(E17,12) -> 44651 | G17: =EOMONTH(F17,12) -> 45016 | H17: =EOMONTH(G17,12) -> 45382 | I17: =EOMONTH(H17,12) -> 45747 | J17: =EOMONTH(I17,12) -> 46112
C18: Revenue from operations | D18: ='P & L'!C8 -> 248702 | E18: ='P & L'!D8 -> 241430.6 | F18: ='P & L'!E8 -> 309762.7 | G18: ='P & L'!F8 -> 428395.6 | H18: ='P & L'!G8 -> 507888.3 | I18: ='P & L'!H8 -> 593580.5 | J18: ='P & L'!I8 -> 688207.4
C19: Revenue growth (Y-o-Y) | D19: 0.24322903 | E19: =(E18/D18)-1 -> -0.029237401 | F19: =(F18/E18)-1 -> 0.28302999 | G19: =(G18/F18)-1 -> 0.38297994 | H19: =(H18/G18)-1 -> 0.1855591 | I19: =(I18/H18)-1 -> 0.16872253 | J19: =(J18/I18)-1 -> 0.15941713
C20: Gross profit margin (%) | D20: ='P & L'!C13 -> 0.15147727 | E20: ='P & L'!D13 -> 0.14862988 | F20: ='P & L'!E13 -> 0.14781896 | G20: ='P & L'!F13 -> 0.15069272 | H20: ='P & L'!G13 -> 0.14795163 | I20: ='P & L'!H13 -> 0.14835983 | J20: ='P & L'!I13 -> 0.15055069
C21: EBITDA margin | D21: ='P & L'!C18 -> 0.085576714 | E21: ='P & L'!D18 -> 0.072196731 | F21: ='P & L'!E18 -> 0.080658517 | G21: ='P & L'!F18 -> 0.084898865 | H21: ='P & L'!G18 -> 0.080800641 | I21: ='P & L'!H18 -> 0.075597665 | J21: ='P & L'!I18 -> 0.075363764
C22: EBIT margin | D22: ='P & L'!C21 -> 0.070522151 | E22: ='P & L'!D21 -> 0.055042319 | F22: ='P & L'!E21 -> 0.064579112 | G22: ='P & L'!F21 -> 0.069985779 | H22: ='P & L'!G21 -> 0.066412438 | I22: ='P & L'!H21 -> 0.060948936 | J22: ='P & L'!I21 -> 0.060295341
C23: EBT margin | D23: ='P & L'!C26 -> 0.070155045 | E23: ='P & L'!D26 -> 0.061444158 | F23: ='P & L'!E26 -> 0.066635525 | G23: ='P & L'!F26 -> 0.071431406 | H23: ='P & L'!G26 -> 0.068151403 | I23: ='P & L'!H26 -> 0.061873158 | J23: ='P & L'!I26 -> 0.059307993
C24: Net profit margin | D24: ='P & L'!C33 -> 0.052310798 | E24: ='P & L'!D33 -> 0.045538138 | F24: ='P & L'!E33 -> 0.048178816 | G24: ='P & L'!F33 -> 0.055517377 | H24: ='P & L'!G33 -> 0.04992456 | I24: ='P & L'!H33 -> 0.045612179 | J24: ='P & L'!I33 -> 0.043164314
C25: Earnings Per Share (EPS) | D25: ='P & L'!C36 -> 20.71 | E25: ='P & L'!D36 -> 16.97 | F25: ='P & L'!E36 -> 23.04 | G25: ='P & L'!F36 -> 36.72 | H25: ='P & L'!G36 -> 38.99 | I25: ='P & L'!H36 -> 41.61 | J25: ='P & L'!I36 -> 45.65
C26: EPS Growth rate Y-o-Y | D26: 0 | E26: =(E25/D25)-1 -> -0.18058909 | F26: =(F25/E25)-1 -> 0.35769004 | G26: =(G25/F25)-1 -> 0.59375 | H26: =(H25/G25)-1 -> 0.061819172 | I26: =(I25/H25)-1 -> 0.067196717 | J26: =(J25/I25)-1 -> 0.097092045
C27: Market price | D27: 2218 | E27: 2885 | F27: 4013 | G27: 341305 | H27: 4570 | I27: 4109.75 | J27: 4075
C28: Price-to-Earnings | D28: =2218/'P & L'!C36 -> 107.09802 | E28: =2885/'P & L'!D36 -> 170.00589 | F28: =4013/'P & L'!E36 -> 174.17535 | G28: =3413.05/'P & L'!F36 -> 92.947985 | H28: =4570/'P & L'!G36 -> 117.20954 | I28: =4109.75/'P & L'!H36 -> 98.768325 | J28: =4075/'P & L'!I36 -> 89.266156
C29: Price to book value | D29: =D27/10 -> 221.8 | E29: =E27/10 -> 288.5 | F29: =F27/10 -> 401.3 | G29: =G27/10 -> 34130.5 | H29: =H27/10 -> 457 | I29: =I27/10 -> 410.975 | J29: =J27/10 -> 407.5
C30: Return on equity | D30: =D25/D27 -> 0.0093372408 | E30: =E25/E27 -> 0.005882149 | F30: =F25/F27 -> 0.0057413406 | G30: =G25/G27 -> 0.00010758706 | H30: =H25/H27 -> 0.0085317287 | I30: =I25/I27 -> 0.010124703 | J30: =J25/J27 -> 0.011202454
C32: Top shareholders | D32: No.of shares | E32: Shareholding % | G32: Market value | I32: Capital structure (in millions)
C33: A. PROMOTERS: | D33: 485747156 | E33: 0.7452 | G33: =E33*'DCF Valuation'!$C$42 -> 1834274.7 | I33: Share price | J33: ='DCF Valuation'!C40 -> 3781
C34: B. PUBLIC SHAREHOLDING: | I34: Outstanding shares | J34: ='DCF Valuation'!C41 -> 651.00578
C35: Central Government | D35: 15248 | E35: 0 | G35: =E35*'DCF Valuation'!$C$42 -> 0 | I35: Market capitalization | J35: =J33*J34 -> 2461452.9
C36: Mutual Funds | D36: 49677262 | E36: 0.0677 | G36: =E36*'DCF Valuation'!$C$42 -> 166640.36 | I36: Less: Cash | J36: ='DCF Valuation'!C45 -> -965.6
C37: Banks | D37: 6187 | E37: 0 | G37: =E37*'DCF Valuation'!$C$42 -> 0 | I37: Add: Debt | J37: ='DCF Valuation'!C44 -> 14597.2
C38: Insurance Companies | D38: 3915195 | E38: 0.0047 | G38: =E38*'DCF Valuation'!$C$42 -> 11568.828 | I38: Enterprise Value | J38: =SUM(J35:J37) -> 2475084.5
C39: Foreign Portfolio Investor | D39: 53208934 | E39: 0.09 | G39: =E39*'DCF Valuation'!$C$42 -> 221530.76
C40: Alternate Investment Funds | D40: 239444 | E40: 0.0007 | G40: =E40*'DCF Valuation'!$C$42 -> 1723.017
C41: Provident Funds/Pension Funds | D41: 5261246 | E41: 0.0146 | G41: =E41*'DCF Valuation'!$C$42 -> 35937.212
C42: Sovereign Wealth Funds | D42: 430903 | E42: 0.0007 | G42: =E42*'DCF Valuation'!$C$42 -> 1723.017
C43: Individuals | D43: 49969654 | E43: 0.0719 | G43: =E43*'DCF Valuation'!$C$42 -> 176978.46
C44: NBFCs | D44: 863 | E44: 0 | G44: =E44*'DCF Valuation'!$C$42 -> 0
C45: Trust | D45: 2297 | E45: 0 | G45: =E45*'DCF Valuation'!$C$42 -> 0
C46: Hindu Undivided Family | D46: 517942 | E46: 0.0007 | G46: =E46*'DCF Valuation'!$C$42 -> 1723.017
C47: Non-Resident Indians | D47: 714736 | E47: 0.0011 | G47: =E47*'DCF Valuation'!$C$42 -> 2707.5981
C48: Clearing Member | D48: 11811 | E48: 0.0012 | G48: =E48*'DCF Valuation'!$C$42 -> 2953.7434
C49: Bodies Corporate | D49: 971836 | E49: 0.0014 | G49: =E49*'DCF Valuation'!$C$42 -> 3446.034
C50: Body Corporate - Ltd Liability Partnership | D50: 42354 | E50: 0.0001 | G50: =E50*'DCF Valuation'!$C$42 -> 246.14529
C51: Total (A+B) | D51: 650733068 | E51: =SUM(E33:F50) -> 1 | G51: =SUM(G33:G50) -> 2461452.9
B67: Key Highlights:
